Workbook

Sheet THÁNG 2
A1: STT | B1: MÃ KHÁCH HÀNG | C1: NHÂN VIÊN | D1: KHÁCH HÀNG | E1: CÔNG VIỆC | F1: SỐ TỜ KHAI | G1: LOẠI HÌNH | H1: NGÀY TỜ KHAI | I1: LOẠI HÀNG | J1: LUỒNG TK | K1: HẢI QUAN | L1: C/O | M1: SỐ INV/VAT | N1: SỐ BILL | O1: SỐ BOOKING | P1: SỐ LƯỢNG | T1: (KIỆN, KG) | U1: SỐ CONTAINER | V1: THÔNG BÁO PHÍ CSHT | W1: SỐ TIỀN CSHT | X1: CẢNG XUẤT - CẢNG NHẬP | Y1: GHI CHÚ
P2: 20' | Q2: 40' | R2: LCL | S2: TC
A4: =ROW( ) -3 -> 1 | B4: =VLOOKUP(D4,DSKH!$A:$B,2,0) -> A-17 | C4: KHÁCH | D4: NHỰA RELIABLE | E4: N | F4: 107949987130 | G4: A12 | H4: 46055 | I4: NL | J4: V | K4: BH | L4: E | M4: INVJYSP251231ZKXS-2299 | N4: 260126265212301 | Q4: 5 | U4: MRSU4112026 MSKU1248240 HASU4111143 MRKU5310810 MRSU6565232 | V4: V3PHT202610910717 | W4: 2500000 | X4: CÁT LÁI
A5: =ROW( ) -3 -> 2 | B5: =VLOOKUP(D5,DSKH!$A:$B,2,0) -> A-17 | C5: KHÁCH | D5: NHỰA RELIABLE | E5: N | F5: 107950043610 | G5: A12 | H5: 46055 | I5: NL | J5: V | K5: BH | L5: KV | M5: 9000338290 | N5: SNKO010260102079 | Q5: 8 | U5: HALU5635561 HLHU8300417 HLHU8456945 SEKU4968806 SKHU6419488 SKHU9407109 SKHU9544694 TRHU4761368 | V5: V3PHT202610910771 | W5: 4000000 | X5: CÁT LÁI
A6: =ROW( ) -3 -> 3 | B6: =VLOOKUP(D6,DSKH!$A:$B,2,0) -> A-17 | C6: KHÁCH | D6: NHỰA RELIABLE | E6: N | F6: 107950115230 | G6: A12 | H6: 46055 | I6: NL | J6: X | K6: BH | M6: 9065601030 | N6: 78440202654 | R6: 1 | T6: 10K / 237KG | X6: TCS
A7: =ROW( ) -3 -> 4 | B7: =VLOOKUP(D7,DSKH!$A:$B,2,0) -> A-17 | C7: KHÁCH | D7: NHỰA RELIABLE | E7: N | F7: 107950142860 | G7: A12 | H7: 46055 | I7: NL | J7: X | K7: BH | M7: U2026023 | N7: 16000790381 | R7: 1 | T7: 1K / 218KG | X7: SCSC
A8: =ROW( ) -3 -> 5 | B8: =VLOOKUP(D8,DSKH!$A:$B,2,0) -> A-39 | C8: KHÁCH | D8: TIGER | E8: N | F8: 107949691840 | G8: E31 | H8: 46055 | I8: NL | J8: X | K8: BH | M8: TI002918 | N8: KWSE2601135 | R8: 1 | T8: 9K / 2842KG | V8: V3PHT202610908477 | W8: 42630 | X8: CÁT LÁI
A9: =ROW( ) -3 -> 6 | B9: =VLOOKUP(D9,DSKH!$A:$B,2,0) -> A-39 | C9: KHÁCH | D9: TIGER | E9: N | F9: 107953321120 | G9: E31 | H9: 46083 | I9: NL | J9: X | K9: BH | M9: C50593271-A | N9: YHHY-0100-6010 | R9: 1 | T9: 2K / 13500KG | V9: V3PHT202610918486 | W9: 202500 | X9: TÂN THUẬN
A10: =ROW( ) -3 -> 7 | B10: =VLOOKUP(D10,DSKH!$A:$B,2,0) -> A-56 | C10: KHÁCH | D10: SANYO - TRANCY | E10: X | F10: 308219633060 | G10: E62 | H10: 46083 | I10: NL | J10: X | K10: BH | M10: SVN025-2026 | N10: 122600036909701 | P10: 1 | U10: SKLU2035522 | V10: V3PHT202610918535 | W10: 250000 | X10: CÁT LÁI
A11: =ROW( ) -3 -> 8 | B11: =VLOOKUP(D11,DSKH!$A:$B,2,0) -> A-597 | C11: =IF(AND(D11<>"", F11<>""), "HẢI YẾN", "") -> HẢI YẾN | D11: WHITTIER WOOD | E11: N | F11: 107947484850 | G11: E11 | H11: 46055 | I11: NL | J11: V | K11: CX | M11: 6409 | N11: YMJAW152233710 | Q11: 1 | U11: TGBU6146580 | V11: 263650289166 | W11: 500000 | X11: CAT LAI | Y11: KDTV: BNN2026035043
A12: =ROW( ) -3 -> 9 | B12: =VLOOKUP(D12,DSKH!$A:$B,2,0) -> A-597 | C12: =IF(AND(D12<>"", F12<>""), "HẢI YẾN", "") -> HẢI YẾN | D12: WHITTIER WOOD | E12: N | F12: 107947501760 | G12: E11 | H12: 46055 | I12: NL | J12: X | K12: CX | M12: PO00000161 | N12: 132G500775 | P12: 1 | U12: WHSU2633690 | V12: 202610907733 | W12: 250000 | X12: CAT LAI
A13: =ROW( ) -3 -> 10 | B13: =VLOOKUP(D13,DSKH!$A:$B,2,0) -> A-29 | C13: =IF(AND(D13<>"", F13<>""), "HẢI YẾN", "") -> HẢI YẾN | D13: GIPT - TQVĐ | E13: X | F13: 308214881720 | G13: E62 | H13: 46055 | I13: NL | J13: X | K13: TN | M13: FTM260201 | O13: 26015878 | R13: 1 | T13: 2PP/332.22KG | X13: KHO CAT LAI
A14: =ROW( ) -3 -> 11 | B14: =VLOOKUP(D14,DSKH!$A:$B,2,0) -> A-597 | C14: =IF(AND(D14<>"", F14<>""), "HẢI YẾN", "") -> HẢI YẾN | D14: WHITTIER WOOD | E14: X | F14: 308216093640 | G14: E42 | H14: 46055 | I14: NL | J14: V | K14: CX | M14: 0 5131 | O14: YMJAW490499457 | Q14: 1 | U14: TGBU6764207 | X14: ICD BINH DUONG
A15: =ROW( ) -3 -> 12 | B15: =VLOOKUP(D15,DSKH!$A:$B,2,0) -> A-502 | C15: =IF(AND(D15<>"", F15<>""), "HẢI YẾN", "") -> HẢI YẾN | D15: RYDER | E15: N | F15: 107949907110 | G15: E31 | H15: 46055 | I15: NL | J15: X | K15: DN3 | M15: 980117374 | N15: ONEYSINF79642800 | P15: 1 | U15: ONEU3216535 | V15: 202610910871 | W15: 250000 | X15: CAT LAI
A16: =ROW( ) -3 -> 13 | B16: =VLOOKUP(D16,DSKH!$A:$B,2,0) -> A-502 | C16: =IF(AND(D16<>"", F16<>""), "HẢI YẾN", "") -> HẢI YẾN | D16: RYDER | E16: N | F16: 107949987460 | G16: E31 | H16: 46055 | I16: NL | J16: X | K16: DN3 | M16: 4250423 | N16: 6271255782 | R16: 1 | T16: 1CT/1.5KG | X16: KHO DHL
A17: =ROW( ) -3 -> 14 | B17: =VLOOKUP(D17,DSKH!$A:$B,2,0) -> A-324 | C17: =IF(AND(D17<>"", F17<>""), "HẢI YẾN", "") -> HẢI YẾN | D17: SCHAEFFLER | E17: N | F17: 107951307920 | G17: E31 | H17: 46055 | I17: NL | J17: X | K17: BH | M17: ES0252604300 | N17: AMD49007509 | R17: 1 | T17: 2PK/17.2KG | X17: KHO SCSC
A18: =ROW( ) -3 -> 15 | B18: =VLOOKUP(D18,DSKH!$A:$B,2,0) -> A-324 | C18: =IF(AND(D18<>"", F18<>""), "HẢI YẾN", "") -> HẢI YẾN | D18: SCHAEFFLER | E18: N | F18: 107951309910 | G18: E31 | H18: 46055 | I18: NL | J18: X | K18: BH | M18: 200496/25-26 | N18: DEL10598537 | R18: 1 | T18: 1PP/75KG | X18: KHO TCS
A19: =ROW( ) -3 -> 16 | B19: =VLOOKUP(D19,DSKH!$A:$B,2,0) -> A-324 | C19: =IF(AND(D19<>"", F19<>""), "HẢI YẾN", "") -> HẢI YẾN | D19: SCHAEFFLER | E19: N | F19: 107951319600 | G19: A12 | H19: 46055 | I19: NL | J19: X | K19: BH | M19: VT260129B | N19: 260100406SGN | R19: 1 | T19: 1PK/288KG | X19: KHO SCSC | Y19: CHUNG LÔ
A20: =ROW( ) -3 -> 17 | B20: =VLOOKUP(D20,DSKH!$A:$B,2,0) -> A-324 | C20: =IF(AND(D20<>"", F20<>""), "HẢI YẾN", "") -> HẢI YẾN | D20: SCHAEFFLER | E20: N | F20: 107951315030 | G20: E31 | H20: 46055 | I20: NL | J20: X | K20: BH | M20: VT260129
A21: =ROW( ) -3 -> 18 | B21: =VLOOKUP(D21,DSKH!$A:$B,2,0) -> A-324 | C21: =IF(AND(D21<>"", F21<>""), "HẢI YẾN", "") -> HẢI YẾN | D21: SCHAEFFLER | E21: N | F21: 107951405920 | G21: A12 | H21: 46055 | I21: NL | J21: X | K21: BH | M21: INAQ260112 | N21: 260100436SGN | R21: 1 | T21: 1PK/38KG | X21: KHO TCS
A22: =ROW( ) -3 -> 19 | B22: =VLOOKUP(D22,DSKH!$A:$B,2,0) -> A-324 | C22: =IF(AND(D22<>"", F22<>""), "HẢI YẾN", "") -> HẢI YẾN | D22: SCHAEFFLER | E22: N | F22: 107952250560 | G22: A41 | H22: 46055 | I22: NL | J22: X | K22: BH | M22: 124734948 | N22: I267505 | R22: 1 | T22: 1CT/54KG | X22: KHO TCS
A23: =ROW( ) -3 -> 20 | B23: =VLOOKUP(D23,DSKH!$A:$B,2,0) -> A-29 | C23: =IF(AND(D23<>"", F23<>""), "HẢI YẾN", "") -> HẢI YẾN | D23: GIPT - TQVĐ | E23: X | F23: 308218160740 | G23: E62 | H23: 46055 | I23: NL | J23: X | K23: TN | M23: R260201 | O23: 2166029340 | Q23: 1 | U23: OOCU7184019 | X23: CÁI MÉP THỊ VẢI
A24: =ROW( ) -3 -> 21 | B24: =VLOOKUP(D24,DSKH!$A:$B,2,0) -> A-324 | C24: =IF(AND(D24<>"", F24<>""), "HẢI YẾN", "") -> HẢI YẾN | D24: SCHAEFFLER | E24: N | F24: 107953064000 | G24: A12 | H24: 46056 | I24: NL | J24: X | K24: BH | M24: UI2526EXP00242 | N24: BOM20552930 | R24: 1 | T24: 1PK/36KG | X24: KHO SCSC
A25: =ROW( ) -3 -> 22 | B25: =VLOOKUP(D25,DSKH!$A:$B,2,0) -> A-502 | C25: =IF(AND(D25<>"", F25<>""), "HẢI YẾN", "") -> HẢI YẾN | D25: RYDER | E25: N | F25: 107953137460 | G25: E31 | H25: 46056 | I25: NL | J25: X | K25: DN3 | M25: 4251821 | N25: 5014370082 | R25: 1 | T25: 1CT/1.6KG | X25: KHO DHL
A26: =ROW( ) -3 -> 23 | B26: =VLOOKUP(D26,DSKH!$A:$B,2,0) -> A-502 | C26: =IF(AND(D26<>"", F26<>""), "HẢI YẾN", "") -> HẢI YẾN | D26: RYDER | E26: N | F26: 107953514430 | G26: H11 | H26: 46056 | I26: NL | J26: V | K26: DN3 | M26: S26012901-280-PMD | N26: 1Z4WF3636795284280 | R26: 1 | T26: 2CT/7.5KG | X26: KHO UPS
A27: =ROW( ) -3 -> 24 | B27: =VLOOKUP(D27,DSKH!$A:$B,2,0) -> A-502 | C27: =IF(AND(D27<>"", F27<>""), "HẢI YẾN", "") -> HẢI YẾN | D27: RYDER | E27: X | F27: 308219721260 | G27: E62 | H27: 46056 | I27: NL | J27: X | K27: DN3 | M27: RD260203-KING-CA | R27: 1 | T27: 10CT/62,2KG | X27: KHO DHL
A28: =ROW( ) -3 -> 25 | B28: =VLOOKUP(D28,DSKH!$A:$B,2,0) -> A-502 | C28: =IF(AND(D28<>"", F28<>""), "HẢI YẾN", "") -> HẢI YẾN | D28: RYDER | E28: X | F28: 308220523460 | G28: E62 | H28: 46056 | I28: NL | J28: V | K28: DN3 | M28: RD260203-SIL-NO | R28: 1 | T28: 1CT/0,8KG | X28: KHO FEDEX
A29: =ROW( ) -3 -> 26 | B29: =VLOOKUP(D29,DSKH!$A:$B,2,0) -> A-502 | C29: =IF(AND(D29<>"", F29<>""), "HẢI YẾN", "") -> HẢI YẾN | D29: RYDER | E29: X | F29: 308220570950 | G29: E62 | H29: 46056 | I29: NL | J29: V | K29: DN3 | M29: RD260203-SIL-AU | R29: 1 | T29: 1CT/1,5KG | X29: KHO DHL
A30: =ROW( ) -3 -> 27 | B30: =VLOOKUP(D30,DSKH!$A:$B,2,0) -> A-597 | C30: =IF(AND(D30<>"", F30<>""), "HẢI YẾN", "") -> HẢI YẾN | D30: WHITTIER WOOD | E30: X | F30: 308220855300 | G30: E42 | H30: 46056 | I30: NL | J30: V | K30: CX | M30: 0 5132 | O30: YMJAW490498992 | Q30: 1 | U30: YMMU6192084 | V30: 264826741762 | W30: 500000 | X30: SOTRANS ICD
A31: =ROW( ) -3 -> 28 | B31: =VLOOKUP(D31,DSKH!$A:$B,2,0) -> A-596 | C31: =IF(AND(D31<>"", F31<>""), "HẢI YẾN", "") -> HẢI YẾN | D31: LEADERSHIP | E31: N | F31: 107953716030 | G31: E15 | H31: 46056 | I31: NL | J31: X | K31: TN | M31: 43 | S31: 1 | T31: 48PK/455.04KG
A32: =ROW( ) -3 -> 29 | B32: =VLOOKUP(D32,DSKH!$A:$B,2,0) -> A-37 | C32: =IF(AND(D32<>"", F32<>""), "HOÀI", "") -> HOÀI | D32: FLEMING | E32: X | F32: 308215019950 | G32: E42 | H32: 46055 | I32: NL | J32: X | K32: CX | M32: PB-2511083 | R32: 1 | T32: 3K/ 18.48KG/0,07CBM | X32: DAMCO
A33: =ROW( ) -3 -> 30 | B33: =VLOOKUP(D33,DSKH!$A:$B,2,0) -> A-37 | C33: =IF(AND(D33<>"", F33<>""), "HOÀI", "") -> HOÀI | D33: FLEMING | E33: X | F33: 308219165940 | G33: E42 | H33: 46056 | I33: NL | J33: X | K33: CX | M33: PB-2511031/2511032 | R33: 1 | T33: 51K/ 314.16KG/1,26CBM | X33: DAMCO
A34: =ROW( ) -3 -> 31 | B34: =VLOOKUP(D34,DSKH!$A:$B,2,0) -> A-37 | C34: =IF(AND(D34<>"", F34<>""), "HOÀI", "") -> HOÀI | D34: FLEMING | E34: X | F34: 308219141330 | G34: E42 | H34: 46056 | I34: NL | J34: X | K34: CX | M34: PB-2511033 | R34: 1 | T34: 126K/ 776.16KG/3,12CBM | X34: DAMCO
A35: =ROW( ) -3 -> 32 | B35: =VLOOKUP(D35,DSKH!$A:$B,2,0) -> A-37 | C35: =IF(AND(D35<>"", F35<>""), "HOÀI", "") -> HOÀI | D35: FLEMING | E35: X | F35: 308215055800 | G35: E42 | H35: 46055 | I35: NL | J35: X | K35: CX | M35: HSH-2508148/2 | R35: 1 | T35: 540K/ 7338.6KG/27,027CBM | X35: TBS
A36: =ROW( ) -3 -> 33 | B36: =VLOOKUP(D36,DSKH!$A:$B,2,0) -> A-298 | C36: =IF(AND(D36<>"", F36<>""), "THẢO", "") -> THẢO | D36: WANHUA | E36: =IF(LEFT(F36,1)="1","N","X") -> N | F36: 107950751160 | G36: A41 | H36: 46055 | I36: NL | J36: V | K36: CNC | M36: SG4056501VN | N36: 263845486 | P36: 2 | T36: 160K/43.720KG | U36: MSKU5602829 TRHU1558038 | X36: TC NHON TRACH | Y36: 0317794954QZH0004694
A37: =ROW( ) -3 -> 34 | B37: =VLOOKUP(D37,DSKH!$A:$B,2,0) -> A-502 | C37: =IF(AND(D37<>"", F37<>""), "THẢO", "") -> THẢO | D37: RYDER | E37: =IF(LEFT(F37,1)="1","N","X") -> N | F37: 107949619630 | G37: E31 | H37: 46055 | I37: NL | J37: X | K37: DN3 | M37: 4250492 | N37: 6271256003 | R37: 1 | T37: 1K/1,6KG | X37: DHL
A38: =ROW( ) -3 -> 35 | B38: =VLOOKUP(D38,DSKH!$A:$B,2,0) -> A-502 | C38: =IF(AND(D38<>"", F38<>""), "THẢO", "") -> THẢO | D38: RYDER | E38: =IF(LEFT(F38,1)="1","N","X") -> N | F38: 107950099130 | G38: A12 | H38: 46055 | I38: NL | J38: X | K38: DN3 | M38: VN260130XF-FEDEX-N | N38: 412669257903 | R38: 1 | T38: 1K/2,6KG | X38: FEDEX
A39: =ROW( ) -3 -> 36 | B39: =VLOOKUP(D39,DSKH!$A:$B,2,0) -> A-502 | C39: =IF(AND(D39<>"", F39<>""), "THẢO", "") -> THẢO | D39: RYDER | E39: =IF(LEFT(F39,1)="1","N","X") -> X | F39: 308211366760 | G39: E52 | H39: 46055 | I39: NL | J39: X | K39: DN3 | M39: RD260203GC09-BOA-VNGC | R39: 1 | T39: 2K/645,21KG | X39: KNQ LF LOGISTICS
A40: =ROW( ) -3 -> 37 | B40: =VLOOKUP(D40,DSKH!$A:$B,2,0) -> A-502 | C40: =IF(AND(D40<>"", F40<>""), "THẢO", "") -> THẢO | D40: RYDER | E40: =IF(LEFT(F40,1)="1","N","X") -> X | F40: 308215724410 | G40: E62 | H40: 46055 | I40: NL | J40: X | K40: DN3 | M40: RD260203-BOA-VN | R40: 1 | T40: 2K/942,6KG | X40: KNQ LF LOGISTICS
A41: =ROW( ) -3 -> 38 | B41: =VLOOKUP(D41,DSKH!$A:$B,2,0) -> A-213 | C41: =IF(AND(D41<>"", F41<>""), "THẢO", "") -> THẢO | D41: REGENT | E41: =IF(LEFT(F41,1)="1","N","X") -> N | F41: 107944743061 | G41: A12 | H41: 46055 | I41: NL | J41: Đ | K41: NT | L41: E | M41: 20260112003 | N41: CKCOSH2521959UWS | P41: 1 | T41: 227K/26.589,1KG | U41: BEAU2587928 | X41: CAT LAI
...

Sheet THÁNG 3_Tổng hợp
A1: STT | B1: MÃ KHÁCH HÀNG | C1: NHÂN VIÊN | D1: KHÁCH HÀNG | E1: CÔNG VIỆC | F1: SỐ TỜ KHAI | G1: LOẠI HÌNH | H1: NGÀY TỜ KHAI | I1: LOẠI HÀNG | J1: LUỒNG TK | K1: HẢI QUAN | L1: C/O | M1: SỐ INV/VAT | N1: SỐ BILL | O1: SỐ BOOKING | P1: SỐ LƯỢNG | T1: (KIỆN, KG) | U1: SỐ CONTAINER | V1: THÔNG BÁO PHÍ CSHT | W1: SỐ TIỀN CSHT | X1: CẢNG XUẤT - CẢNG NHẬP | Y1: GHI CHÚ
P2: 20' | Q2: 40' | R2: LCL | S2: TC
A4: =ROW( ) -3 -> 1 | B4: =VLOOKUP(D4,DSKH!$A:$B,2,0) -> #N/A | C4: KHÁCH | D4: TÂN PHÚ VN | E4: X | F4: 308298297700 | G4: E62 | H4: 46086 | I4: NL | J4: X | K4: BH | M4: 126/EXP-2026 | Q4: 1 | U4: APZU4765152 | X4: CÁI MÉP
A5: =ROW( ) -3 -> 2 | B5: =VLOOKUP(D5,DSKH!$A:$B,2,0) -> A-39 | C5: KHÁCH | D5: TIGER | E5: N | F5: 108000946324 | G5: H11 | H5: 46079 | I5: NL | J5: D | K5: BH | M5: TG-HCM-370/25-3 | N5: NGODJZ29396-01 | P5: 1 | U5: OOCU0401133 | V5: V3PHT202611107941 | W5: 250000 | X5: SP-ITC | Y5: CHUNG LÔ
A6: =ROW( ) -3 -> 3 | B6: =VLOOKUP(D6,DSKH!$A:$B,2,0) -> A-39 | C6: KHÁCH | D6: TIGER | E6: N | F6: 108000993000 | G6: E31 | H6: 46079 | I6: NL | J6: X | K6: BH | M6: FL-HCM-188/25 | N6: NGODJZ29013
A7: =ROW( ) -3 -> 4 | B7: =VLOOKUP(D7,DSKH!$A:$B,2,0) -> A-39 | C7: KHÁCH | D7: TIGER | E7: N | F7: 108000906860 | G7: E31 | H7: 46079 | I7: NL | J7: X | K7: BH | M7: TG-HCM-370/25-1 | N7: NGODJZ29396-02
A8: =ROW( ) -3 -> 5 | B8: =VLOOKUP(D8,DSKH!$A:$B,2,0) -> A-17 | C8: KHÁCH | D8: NHỰA RELIABLE | E8: N | F8: 108013274020 | G8: A12 | H8: 46083 | I8: NL | J8: V | K8: BH | L8: D | M8: SQZSE-26-0444-3 | N8: SE26020077-01 | Q8: 1 | U8: OOLU4446750 | X8: CÁT LÁI
A9: =ROW( ) -3 -> 6 | B9: =VLOOKUP(D9,DSKH!$A:$B,2,0) -> A-17 | C9: KHÁCH | D9: NHỰA RELIABLE | E9: N | F9: 108013247640 | G9: A12 | H9: 46083 | I9: NL | J9: V | K9: BH | L9: E | M9: INVJYSP260114ZKXS-2325 | N9: 263837697 | Q9: 5 | U9: MSKU1898440 UETU7591993 MSKU1944021 MRSU7567395 MRKU3943296 | V9: V3PHT265254146033 | W9: 2500000 | X9: CÁT LÁI
A10: =ROW( ) -3 -> 7 | B10: =VLOOKUP(D10,DSKH!$A:$B,2,0) -> A-17 | C10: KHÁCH | D10: NHỰA RELIABLE | E10: N | F10: 108013214520 | G10: A12 | H10: 46083 | I10: NL | J10: V | K10: BH | L10: E | M10: INVJYSP260114ZKXS-2323 | N10: 263837670 | Q10: 5 | U10: TCNU1127910 MSKU1585370 HASU4271835 MSKU0223102 MRSU4245646 | V10: V3PHT265250306422 | W10: 2500000 | X10: CÁT LÁI
A11: =ROW( ) -3 -> 8 | B11: =VLOOKUP(D11,DSKH!$A:$B,2,0) -> A-27 | C11: KHÁCH | D11: TRUNG ĐÔNG | E11: N | F11: 108016254840 | G11: E31 | H11: 46084 | I11: NL | J11: X | K11: DN3 | M11: 9670092423 | N11: HDMUDMMA83529200 | Q11: 20 | U11: BMOU5178701 CLKU5017800 HMMU4458286 HMMU4898990 HMMU4977260 HMMU6225679 HMMU6428589 HMMU6445014 HMMU6647490 HMMU6881661 HMMU6895515 HMMU6967615 HMMU7144864 HMMU7169754 KOCU4165828 KOCU4394228 KOCU4741923 KOCU4853939 KOCU5054285 TLLU5814541 | V11: V3PHT202611092966 | W11: 10000000 | X11: CÁT LÁI
A12: =ROW( ) -3 -> 9 | B12: =VLOOKUP(D12,DSKH!$A:$B,2,0) -> A-27 | C12: KHÁCH | D12: TRUNG ĐÔNG | E12: N | F12: 108017990950 | G12: A12 | H12: 46084 | I12: NL | J12: V | K12: DN3 | L12: KV | M12: 40144040 | N12: 265589867 | Q12: 10 | U12: SUDU8984797 MRSU3753262 CAAU9001814 GCXU6390655 CAAU6574582 TCKU6962640 SUDU8801710 MRSU5311763 GCXU5717126 TCNU8805305 | V12: V3PHT202611097908 | W12: 5000000 | X12: CÁT LÁI
A13: =ROW( ) -3 -> 10 | B13: =VLOOKUP(D13,DSKH!$A:$B,2,0) -> A-17 | C13: KHÁCH | D13: NHỰA RELIABLE | E13: N | F13: 108023275360 | G13: A12 | H13: 46086 | I13: NL | J13: V | K13: BH | L13: D | M13: SQZSE-26-0444-1 | N13: EGLV070600043187 | Q13: 4 | U13: CAAU6887885 EGSU1831577 EITU9647028 TXGU6094237 | V13: V3PHT202611110739 | W13: 2000000 | X13: CÁT LÁI
A14: =ROW( ) -3 -> 11 | B14: =VLOOKUP(D14,DSKH!$A:$B,2,0) -> A-17 | C14: KHÁCH | D14: NHỰA RELIABLE | E14: N | F14: 108015527800 | G14: A12 | H14: 46084 | I14: NL | J14: V | K14: BH | L14: D | M14: SQZSE-26-0444-4 | N14: SE26020105 | Q14: 1 | U14: DRYU4246145 | V14: V3PHT202611094047 | W14: 500000 | X14: CÁT LÁI
A15: =ROW( ) -3 -> 12 | B15: =VLOOKUP(D15,DSKH!$A:$B,2,0) -> A-27 | C15: KHÁCH | D15: TRUNG ĐÔNG | E15: N | F15: 108020834500 | G15: E31 | H15: 46085 | I15: NL | J15: X | K15: DN3 | M15: IT-SI-11903 | N15: HDMUDMMA40471100 | Q15: 20 | U15: BMOU5173870 GCXU5034135 HMMU4149245 HMMU4170181 HMMU4291408 HMMU4669653 HMMU4670124 HMMU4680591 HMMU4868070 HMMU4941627 HMMU4941822 HMMU6577324 HMMU6662405 HMMU6792461 HMMU6909500 HMMU7097171 KOCU4114965 KOCU4204164 KOCU4909112 TLLU5293931 | V15: V3PHT202611105165 | W15: 10000000 | X15: CÁT LÁI
A16: =ROW( ) -3 -> 13 | B16: =VLOOKUP(D16,DSKH!$A:$B,2,0) -> #N/A | C16: KHÁCH | D16: YIYAO | E16: KBS | F16: 308258035060 | K16: NT | Y16: 730439902840
A17: =ROW( ) -3 -> 14 | B17: =VLOOKUP(D17,DSKH!$A:$B,2,0) -> #N/A | C17: THÚY | D17: ĐầU Tư Và XâY LắP SàI GòN | E17: N | F17: 108020846730 | G17: G13 | H17: 46085 | I17: MM | J17: D | K17: NT | M17: OTM-SG-260225 | S17: 1
A18: =ROW( ) -3 -> 15 | B18: =VLOOKUP(D18,DSKH!$A:$B,2,0) -> #N/A | C18: THÚY | D18: TALLER - GUG | E18: N | F18: 108028244920 | G18: E13 | H18: 46087 | I18: MM | J18: V | K18: MP | M18: 26HY018D002 | N18: NBFCL26020433 | Q18: 2 | U18: FFAU5015768 SEKU6390830 | V18: CHỜ XÁC ĐỊNH RỒI ĐÓNG SAU | X18: CÁT LÁI
A19: =ROW( ) -3 -> 16 | B19: =VLOOKUP(D19,DSKH!$A:$B,2,0) -> A-324 | C19: HOÀI | D19: SCHAEFFLER | E19: N | F19: 108012829410 | G19: E31 | H19: 46083 | I19: NL | J19: X | K19: BH | M19: 137597374 | N19: I489812 | R19: 1 | T19: 1K/ 6KG | X19: KHO SCSC
A20: =ROW( ) -3 -> 17 | B20: =VLOOKUP(D20,DSKH!$A:$B,2,0) -> A-324 | C20: HOÀI | D20: SCHAEFFLER | E20: N | F20: 108012831840 | G20: E31 | H20: 46083 | I20: NL | J20: X | K20: BH | M20: 137597374 | N20: I497946 | R20: 1 | T20: 3K/ 224.2KG | X20: KHO SCSC | Y20: CHUNG BL
A21: =ROW( ) -3 -> 18 | B21: =VLOOKUP(D21,DSKH!$A:$B,2,0) -> A-324 | C21: HOÀI | D21: SCHAEFFLER | E21: N | F21: 108012834200 | G21: A41 | H21: 46083 | I21: NL | J21: V | K21: BH | M21: 137597374 | N21: I497946
A22: =ROW( ) -3 -> 19 | B22: =VLOOKUP(D22,DSKH!$A:$B,2,0) -> A-324 | C22: HOÀI | D22: SCHAEFFLER | E22: N | F22: 108014581730 | G22: E31 | H22: 46083 | I22: NL | J22: X | K22: BH | M22: 137597374 | N22: I468026 | R22: 1 | T22: 11K/ 229KG | X22: KHO SCSC
A23: =ROW( ) -3 -> 20 | B23: =VLOOKUP(D23,DSKH!$A:$B,2,0) -> A-324 | C23: HOÀI | D23: SCHAEFFLER | E23: N | F23: 108014589760 | G23: E31 | H23: 46083 | I23: NL | J23: X | K23: BH | M23: 137597374 | N23: I443493 | R23: 1 | T23: 4K/ 118KG | X23: KHO SCSC
A24: =ROW( ) -3 -> 21 | B24: =VLOOKUP(D24,DSKH!$A:$B,2,0) -> A-324 | C24: HOÀI | D24: SCHAEFFLER | E24: N | F24: 108014590610 | G24: A41 | H24: 46083 | I24: NL | J24: V | K24: BH | M24: 137597374 | N24: I443308 | R24: 1 | T24: 4K/ 45.9KG | X24: KHO SCSC | Y24: CHUNG BL
A25: =ROW( ) -3 -> 22 | B25: =VLOOKUP(D25,DSKH!$A:$B,2,0) -> A-324 | C25: HOÀI | D25: SCHAEFFLER | E25: N | F25: 108014593150 | G25: A12 | H25: 46083 | I25: NL | J25: X | K25: BH | M25: 137597374
A26: =ROW( ) -3 -> 23 | B26: =VLOOKUP(D26,DSKH!$A:$B,2,0) -> A-324 | C26: HOÀI | D26: SCHAEFFLER | E26: N | F26: 108015864940 | G26: A12 | H26: 46083 | I26: NL | J26: X | K26: BH | M26: 137597374 | N26: 712659987501 | R26: 1 | T26: 9K/ 9.3KG | X26: KHO FEDEX
A27: =ROW( ) -3 -> 24 | B27: =VLOOKUP(D27,DSKH!$A:$B,2,0) -> A-324 | C27: HOÀI | D27: SCHAEFFLER | E27: N | F27: 108015883360 | G27: A12 | H27: 46083 | I27: NL | J27: V | K27: BH | L27: REX | M27: 137597374 | N27: I487392 | R27: 1 | T27: 1K/ 338KG | X27: KHO SCSC
A28: =ROW( ) -3 -> 25 | B28: =VLOOKUP(D28,DSKH!$A:$B,2,0) -> A-650 | C28: HOÀI | D28: BRONCO | E28: X | F28: 308279208550 | G28: E42 | H28: 46083 | I28: NL | J28: Đ | K28: TN | M28: 1 | S28: 1 | T28: 263K/1993.98KG
A29: =ROW( ) -3 -> 26 | B29: =VLOOKUP(D29,DSKH!$A:$B,2,0) -> A-15 | C29: HOÀI | D29: PENFLEX | E29: N | F29: 108016916930 | G29: A12 | H29: 46083 | I29: NL | J29: X | K29: TN | M29: P7900 | N29: 889091427627 | R29: 1 | T29: 1K/ 5.5KG | X29: KHO FEDEX
A30: =ROW( ) -3 -> 27 | B30: =VLOOKUP(D30,DSKH!$A:$B,2,0) -> A-15 | C30: HOÀI | D30: PENFLEX | E30: N | F30: 108016959300 | G30: A12 | H30: 46083 | I30: NL | J30: X | K30: TN | M30: RE/2026091 | N30: 888747229609 | R30: 1 | T30: 1K/ 11KG | X30: KHO FEDEX
A31: =ROW( ) -3 -> 28 | B31: =VLOOKUP(D31,DSKH!$A:$B,2,0) -> A-15 | C31: HOÀI | D31: PENFLEX | E31: N | F31: 108017010620 | G31: A12 | H31: 46083 | I31: NL | J31: X | K31: TN | M31: 3 | N31: 888982402513 | R31: 1 | T31: 1K/ 3KG | X31: KHO FEDEX
A32: =ROW( ) -3 -> 29 | B32: =VLOOKUP(D32,DSKH!$A:$B,2,0) -> A-37 | C32: HOÀI | D32: FLEMING | E32: X | F32: 308291037410 | G32: E42 | H32: 46085 | I32: NL | J32: X | K32: CX | M32: PB-2512004/005/008-2/009-2 | R32: 1 | T32: 202K/ 11009.46KG/3.97CBM | X32: TBS
A33: =ROW( ) -3 -> 30 | B33: =VLOOKUP(D33,DSKH!$A:$B,2,0) -> A-37 | C33: HOÀI | D33: FLEMING | E33: X | F33: 308285431440 | G33: E42 | H33: 46083 | I33: NL | J33: X | K33: CX | M33: HSH-2510015-2508150/3 | O33: SGN3065610 | P33: 1 | T33: 688K/ 5944.32KG/26.523CBM | U33: WNGU2593870 | X33: BINH DUONG
A34: =ROW( ) -3 -> 31 | B34: =VLOOKUP(D34,DSKH!$A:$B,2,0) -> A-37 | C34: HOÀI | D34: FLEMING | E34: X | F34: 308285372050 | G34: E42 | H34: 46083 | I34: NL | J34: X | K34: CX | M34: HSH-2510015-2508150/1 | O34: SGN3065610 | Q34: 1 | T34: 1540K/ 19388.6KG/59CBM | U34: TCLU1848458 | X34: BINH DUONG
A35: =ROW( ) -3 -> 32 | B35: =VLOOKUP(D35,DSKH!$A:$B,2,0) -> A-37 | C35: HOÀI | D35: FLEMING | E35: X | F35: 308285399020 | G35: E42 | H35: 46083 | I35: NL | J35: X | K35: CX | M35: HSH-2510015-2508150/2 | O35: SGN3065610 | Q35: 1 | T35: 1232K/ 9440.2KG/59.377CBM | U35: CMAU4842070 | X35: BINH DUONG
A36: =ROW( ) -3 -> 33 | B36: =VLOOKUP(D36,DSKH!$A:$B,2,0) -> A-37 | C36: HOÀI | D36: FLEMING | E36: X | F36: 308291498820 | G36: E42 | H36: 46085 | I36: NL | J36: X | K36: CX | M36: HSH-2508150/2 | R36: 1 | T36: 185K/ 1598.4KG/7.132CBM | X36: TBS
A37: =ROW( ) -3 -> 34 | B37: =VLOOKUP(D37,DSKH!$A:$B,2,0) -> A-37 | C37: HOÀI | D37: FLEMING | E37: X | F37: 308291534630 | G37: E42 | H37: 46085 | I37: NL | J37: X | K37: CX | M37: HSH-2508150/1 | R37: 1 | T37: 154K/ 1330.56KG/5.937CBM | X37: TBS
A38: =ROW( ) -3 -> 35 | B38: =VLOOKUP(D38,DSKH!$A:$B,2,0) -> A-131 | C38: HOÀI | D38: OPTIMA/LYNN | E38: X | F38: 308283884700 | G38: B11 | H38: 46083 | I38: NL | J38: X | K38: DN3 | M38: 8650203516 | O38: 235600328186 | Q38: 1 | T38: 1750K/ 6388KG | U38: TCNU2122512 | V38: 202611081333 | W38: 500000 | X38: CAT LAI
A39: =ROW( ) -3 -> 36 | B39: =VLOOKUP(D39,DSKH!$A:$B,2,0) -> A-131 | C39: HOÀI | D39: OPTIMA/LYNN | E39: X | F39: 308284068910 | G39: B11 | H39: 46083 | I39: NL | J39: X | K39: DN3 | M39: 8650203739 | R39: 1 | T39: 700K/ 3344KG | X39: TBS
A40: =ROW( ) -3 -> 37 | B40: =VLOOKUP(D40,DSKH!$A:$B,2,0) -> A-131 | C40: HOÀI | D40: OPTIMA/LYNN | E40: X | F40: 308288040710 | G40: B11 | H40: 46084 | I40: NL | J40: X | K40: DN3 | M40: 8650203742 | R40: 1 | T40: 696K/ 3503KG | X40: TBS
A41: =ROW( ) -3 -> 38 | B41: =VLOOKUP(D41,DSKH!$A:$B,2,0) -> A-131 | C41: HOÀI | D41: OPTIMA/LYNN | E41: X | F41: 308290430030 | G41: B11 | H41: 46084 | I41: NL | J41: X | K41: DN3 | M41: 8650204322 | O41: SGNM91458500 | Q41: 1 | T41: 1356K/ 7284KG | U41: GAOU6187749 | V41: 202611098302 | W41: 500000 | X41: CANG PHUOC LONG
...

Sheet THÁNG 4_Tổng hợp
A1: STT | B1: MÃ KHÁCH HÀNG | C1: NHÂN VIÊN | D1: KHÁCH HÀNG | E1: CÔNG VIỆC | F1: SỐ TỜ KHAI | G1: LOẠI HÌNH | H1: NGÀY TỜ KHAI | I1: LOẠI HÀNG | J1: LUỒNG TK | K1: HẢI QUAN | L1: C/O | M1: SỐ INV/VAT | N1: SỐ BILL | O1: SỐ BOOKING | P1: SỐ LƯỢNG | T1: (KIỆN, KG) | U1: SỐ CONTAINER | V1: THÔNG BÁO PHÍ CSHT | W1: SỐ TIỀN CSHT | X1: CẢNG XUẤT - CẢNG NHẬP | Y1: GHI CHÚ
P2: 20' | Q2: 40' | R2: LCL | S2: TC
A4: =ROW( ) -3 -> 1 | B4: =VLOOKUP(D4,DSKH!$A:$B,2,0) -> A-42 | C4: MY | D4: SHIN FUNG | E4: X | F4: 308390237540 | G4: B11 | H4: 46113 | I4: NL | J4: X | K4: TN | M4: 142026-BILBAO | O4: SGNE31757700 | P4: 1 | T4: 24K/13.942,7KG | U4: BSIU2789512 | V4: 202611323384 | W4: 250000 | X4: CÁT LÁI | Y4: CHUNG LÔ
A5: =ROW( ) -3 -> 2 | B5: =VLOOKUP(D5,DSKH!$A:$B,2,0) -> A-42 | C5: MY | D5: SHIN FUNG | E5: X | F5: 308390246200 | G5: B11 | H5: 46113 | I5: NL | J5: X | K5: TN
A6: =ROW( ) -3 -> 3 | B6: =VLOOKUP(D6,DSKH!$A:$B,2,0) -> A-144 | C6: MY | D6: JINGGUANG | E6: N | F6: 108110105940 | G6: E15 | H6: 46113 | I6: NL | J6: X | K6: CX | M6: 286 | S6: 1 | T6: 1K/62KG
A7: =ROW( ) -3 -> 4 | B7: =VLOOKUP(D7,DSKH!$A:$B,2,0) -> A-144 | C7: MY | D7: JINGGUANG | E7: N | F7: 108110101300 | G7: E15 | H7: 46113 | I7: NL | J7: X | K7: CX | M7: 281 | S7: 1 | T7: 27K/674,196KG
A8: =ROW( ) -3 -> 5 | B8: =VLOOKUP(D8,DSKH!$A:$B,2,0) -> A-144 | C8: MY | D8: JINGGUANG | E8: N | F8: 108110075840 | G8: E15 | H8: 46113 | I8: NL | J8: X | K8: CX | M8: 138 | S8: 1 | T8: 3K/15KG
A9: =ROW( ) -3 -> 6 | B9: =VLOOKUP(D9,DSKH!$A:$B,2,0) -> A-144 | C9: MY | D9: JINGGUANG | E9: N | F9: 108109842960 | G9: E15 | H9: 46113 | I9: NL | J9: X | K9: CX | M9: 749 | S9: 1 | T9: 53K/899,08KG
A10: =ROW( ) -3 -> 7 | B10: =VLOOKUP(D10,DSKH!$A:$B,2,0) -> A-144 | C10: MY | D10: JINGGUANG | E10: N | F10: 108108168930 | G10: E13 | H10: 46113 | I10: NL | J10: V | K10: CX | M10: 12 | S10: 1 | T10: 1K/1.413KG
A11: =ROW( ) -3 -> 8 | B11: =VLOOKUP(D11,DSKH!$A:$B,2,0) -> A-144 | C11: MY | D11: JINGGUANG | E11: X | F11: 308389848010 | G11: E42 | H11: 46113 | I11: NL | J11: X | K11: CX | M11: JG-XN2-20260401 | S11: 1 | T11: 474K/4.674,568KG
A12: =ROW( ) -3 -> 9 | B12: =VLOOKUP(D12,DSKH!$A:$B,2,0) -> A-144 | C12: MY | D12: JINGGUANG | E12: X | F12: 308389657020 | G12: E42 | H12: 46113 | I12: NL | J12: X | K12: CX | M12: 326 | S12: 1 | T12: 232K/11.538,69KG
A13: =ROW( ) -3 -> 10 | B13: =VLOOKUP(D13,DSKH!$A:$B,2,0) -> A-144 | C13: MY | D13: JINGGUANG | E13: X | F13: 308388495940 | G13: E42 | H13: 46113 | I13: NL | J13: X | K13: CX | M13: 325 | S13: 1 | T13: 74K/6.660KG
A14: =ROW( ) -3 -> 11 | B14: =VLOOKUP(D14,DSKH!$A:$B,2,0) -> A-144 | C14: MY | D14: JINGGUANG | E14: X | F14: 308388280930 | G14: E42 | H14: 46113 | I14: NL | J14: X | K14: CX | M14: 324 | S14: 1 | T14: 128K/11.325,13KG
A15: =ROW( ) -3 -> 12 | B15: =VLOOKUP(D15,DSKH!$A:$B,2,0) -> A-144 | C15: MY | D15: JINGGUANG | E15: X | F15: 308388236130 | G15: E42 | H15: 46113 | I15: NL | J15: V | K15: CX | M15: 323 | S15: 1 | T15: 217K/2.513,54KG
A16: =ROW( ) -3 -> 13 | B16: =VLOOKUP(D16,DSKH!$A:$B,2,0) -> A-144 | C16: MY | D16: JINGGUANG | E16: X | F16: 308388185250 | G16: E42 | H16: 46113 | I16: NL | J16: X | K16: CX | M16: 322 | S16: 1 | T16: 29K/358,66KG
A17: =ROW( ) -3 -> 14 | B17: =VLOOKUP(D17,DSKH!$A:$B,2,0) -> A-144 | C17: MY | D17: JINGGUANG | E17: X | F17: 308388030440 | G17: E42 | H17: 46113 | I17: NL | J17: X | K17: CX | M17: 321 | S17: 1 | T17: 415K/6.325,3KG
A18: =ROW( ) -3 -> 15 | B18: =VLOOKUP(D18,DSKH!$A:$B,2,0) -> A-144 | C18: MY | D18: JINGGUANG | E18: X | F18: 308387729220 | G18: E42 | H18: 46113 | I18: NL | J18: X | K18: CX | M18: JG-XN5-20260401 | S18: 1 | T18: 2K/60,352KG
A19: =ROW( ) -3 -> 16 | B19: =VLOOKUP(D19,DSKH!$A:$B,2,0) -> A-57 | C19: MY | D19: OT MOTOR | E19: N | F19: 108112222520 | G19: E13 | H19: 46114 | I19: NL | J19: X | K19: NT | M19: I-260251 | N19: 8701 9759 1377 | R19: 1 | T19: 1K/0,3KG
A20: =ROW( ) -3 -> 17 | B20: =VLOOKUP(D20,DSKH!$A:$B,2,0) -> A-56 | C20: MY | D20: NHẬT VIỆT - TRANCY | E20: X | F20: 308392330650 | G20: B11 | H20: 46114 | I20: NL | J20: X | K20: DN1 | M20: NVC-26/04-01 | O20: MPSHA2604071 | R20: 1 | T20: 1K/77,53KG | X20: KHO CÁT LÁI
A21: =ROW( ) -3 -> 18 | B21: =VLOOKUP(D21,DSKH!$A:$B,2,0) -> A-144 | C21: MY | D21: JINGGUANG | E21: X | F21: 308392137930 | G21: E42 | H21: 46114 | I21: NL | J21: X | K21: CX | M21: 327 | S21: 1 | T21: 1K/16,5KG
A22: =ROW( ) -3 -> 19 | B22: =VLOOKUP(D22,DSKH!$A:$B,2,0) -> A-144 | C22: MY | D22: JINGGUANG | E22: X | F22: 308392185200 | G22: E42 | H22: 46114 | I22: NL | J22: X | K22: CX | M22: 328 | S22: 1 | T22: 18K/1.504,54KG
A23: =ROW( ) -3 -> 20 | B23: =VLOOKUP(D23,DSKH!$A:$B,2,0) -> A-144 | C23: MY | D23: JINGGUANG | E23: X | F23: 308393100430 | G23: E42 | H23: 46114 | I23: NL | J23: X | K23: CX | M23: 329 | S23: 1 | T23: 104K/28.869KG
A24: =ROW( ) -3 -> 21 | B24: =VLOOKUP(D24,DSKH!$A:$B,2,0) -> A-144 | C24: MY | D24: JINGGUANG | E24: X | F24: 308393228420 | G24: E42 | H24: 46114 | I24: NL | J24: X | K24: CX | M24: 330 | S24: 1 | T24: 92K/18.265,68KG
A25: =ROW( ) -3 -> 22 | B25: =VLOOKUP(D25,DSKH!$A:$B,2,0) -> A-144 | C25: MY | D25: JINGGUANG | E25: X | F25: 308393475040 | G25: E42 | H25: 46114 | I25: NL | J25: X | K25: CX | M25: 331 | S25: 1 | T25: 280K/22.313,08KG
A26: =ROW( ) -3 -> 23 | B26: =VLOOKUP(D26,DSKH!$A:$B,2,0) -> A-144 | C26: MY | D26: JINGGUANG | E26: X | F26: 308393627860 | G26: E42 | H26: 46114 | I26: NL | J26: X | K26: CX | M26: 332 | S26: 1 | T26: 153K/12.535,2KG
A27: =ROW( ) -3 -> 24 | B27: =VLOOKUP(D27,DSKH!$A:$B,2,0) -> A-144 | C27: MY | D27: JINGGUANG | E27: X | F27: 308393682940 | G27: E42 | H27: 46114 | I27: NL | J27: X | K27: CX | M27: 333 | S27: 1 | T27: 146K/12.940,71KG
A28: =ROW( ) -3 -> 25 | B28: =VLOOKUP(D28,DSKH!$A:$B,2,0) -> A-144 | C28: MY | D28: JINGGUANG | E28: X | F28: 308393858860 | G28: E42 | H28: 46114 | I28: NL | J28: X | K28: CX | M28: 334 | S28: 1 | T28: 176K/11.585,04KG
A29: =ROW( ) -3 -> 26 | B29: =VLOOKUP(D29,DSKH!$A:$B,2,0) -> A-144 | C29: MY | D29: JINGGUANG | E29: N | F29: 108110126940 | G29: E15 | H29: 46114 | I29: NL | J29: X | K29: CX | M29: 350 | S29: 1 | T29: 112CT/252,58KG
A30: =ROW( ) -3 -> 27 | B30: =VLOOKUP(D30,DSKH!$A:$B,2,0) -> A-212 | C30: MY | D30: LEADER | E30: N | F30: 108118278660 | G30: E15 | H30: 46115 | I30: NL | J30: X | K30: TN | M30: 475 | S30: 1 | T30: 1.483K/29,202,42
A31: =ROW( ) -3 -> 28 | B31: =VLOOKUP(D31,DSKH!$A:$B,2,0) -> A-212 | C31: MY | D31: LEADER | E31: N | F31: 108118292330 | G31: E15 | H31: 46115 | I31: NL | J31: X | K31: TN | M31: 476 | S31: 1 | T31: 1.296K/27.027,98KG
A32: =ROW( ) -3 -> 29 | B32: =VLOOKUP(D32,DSKH!$A:$B,2,0) -> A-502 | C32: HUYỀN | D32: RYDER | E32: N | F32: 108105128350 | G32: E31 | H32: 46113 | I32: NL | J32: X | K32: DN3 | M32: 20260331-RIL-522 | N32: 889981937522 | R32: 1
A33: =ROW( ) -3 -> 30 | B33: =VLOOKUP(D33,DSKH!$A:$B,2,0) -> A-502 | C33: HUYỀN | D33: RYDER | E33: N | F33: 108105891940 | G33: E31 | H33: 46113 | I33: NL | J33: X | K33: DN3 | M33: C013102603001 | N33: 280326PL2026036032 | R33: 1 | T33: 3PP/1.446KG | V33: 202611327989 | W33: 21690
A34: =ROW( ) -3 -> 31 | B34: =VLOOKUP(D34,DSKH!$A:$B,2,0) -> A-502 | C34: HUYỀN | D34: RYDER | E34: N | F34: 108107653400 | G34: E31 | H34: 46113 | I34: NL | J34: V | K34: DN3 | M34: M20260326-RIL | N34: HKGHCM26030132 | Q34: 1 | U34: SEGU5539503 | V34: 202611328049 | W34: 500000 | X34: CAT LAI | Y34: CHUNG LÔ
A35: =ROW( ) -3 -> 32 | B35: =VLOOKUP(D35,DSKH!$A:$B,2,0) -> A-502 | C35: HUYỀN | D35: RYDER | E35: N | F35: 108107703210 | G35: E31 | H35: 46113 | I35: NL | J35: X | K35: DN3 | M35: M20260326-RIL
A36: =ROW( ) -3 -> 33 | B36: =VLOOKUP(D36,DSKH!$A:$B,2,0) -> A-502 | C36: HUYỀN | D36: RYDER | E36: N | F36: 108107724100 | G36: E31 | H36: 46113 | I36: NL | J36: X | K36: DN3 | M36: M20260326-SZ
A37: =ROW( ) -3 -> 34 | B37: =VLOOKUP(D37,DSKH!$A:$B,2,0) -> A-502 | C37: HUYỀN | D37: RYDER | E37: N | F37: 108107758360 | G37: E31 | H37: 46113 | I37: NL | J37: V | K37: DN3 | M37: M20260326-SZ
A38: =ROW( ) -3 -> 35 | B38: =VLOOKUP(D38,DSKH!$A:$B,2,0) -> A-502 | C38: HUYỀN | D38: RYDER | E38: N | F38: 108108662540 | G38: E31 | H38: 46113 | I38: NL | J38: X | K38: DN3 | M38: M20260326-XF
A39: =ROW( ) -3 -> 36 | B39: =VLOOKUP(D39,DSKH!$A:$B,2,0) -> A-502 | C39: HUYỀN | D39: RYDER | E39: N | F39: 108108665560 | G39: E31 | H39: 46113 | I39: NL | J39: X | K39: DN3 | M39: M20260326-XF
A40: =ROW( ) -3 -> 37 | B40: =VLOOKUP(D40,DSKH!$A:$B,2,0) -> A-502 | C40: HUYỀN | D40: RYDER | E40: X | F40: 308386687400 | G40: E62 | H40: 46113 | I40: NL | J40: X | K40: DN3 | M40: RD260401-GROOVE-DK | O40: SGNCPH159333V | R40: 1 | T40: 2PP/531.96KG | X40: CAT LAI KHO 1
A41: =ROW( ) -3 -> 38 | B41: =VLOOKUP(D41,DSKH!$A:$B,2,0) -> A-502 | C41: HUYỀN | D41: RYDER | E41: X | F41: 308389790830 | G41: E62 | H41: 46114 | I41: NL | J41: X | K41: DN3 | M41: RD260401-AGUILAR-FI | O41: 26019110 | R41: 1 | T41: 8PP/1543.95KG | V41: 202611323466 | W41: 23160 | X41: CAT LAI KHO 5
...

Sheet THÁNG 5_Tổng hợp
A1: STT | B1: MÃ KHÁCH HÀNG | C1: NHÂN VIÊN | D1: KHÁCH HÀNG | E1: CÔNG VIỆC | F1: SỐ TỜ KHAI | G1: LOẠI HÌNH | H1: NGÀY TỜ KHAI | I1: LOẠI HÀNG | J1: LUỒNG TK | K1: HẢI QUAN | L1: C/O | M1: SỐ INV/VAT | N1: SỐ BILL | O1: SỐ BOOKING | P1: SỐ LƯỢNG | T1: (KIỆN, KG) | U1: SỐ CONTAINER | V1: THÔNG BÁO PHÍ CSHT | W1: SỐ TIỀN CSHT | X1: CẢNG XUẤT - CẢNG NHẬP | Y1: GHI CHÚ | Z1: TRẠNG THÁI LÔ HÀNG
P2: 20' | Q2: 40' | R2: LCL | S2: TC
A4: 1 | B4: =VLOOKUP(D4,DSKH!$A:$B,2,0) -> A-17 | C4: KHÁCH | D4: NHỰA RELIABLE | E4: N | F4: 108203836640 | G4: A12 | H4: 46146 | I4: NL | J4: V | K4: BH | L4: E | M4: INVJYSP260316ZKXS-2515 | N4: 268974350 | Q4: 5 | U4: CAAU8933871 TGBU5255289 SUDU5917584 CAAU4697490 CAAU6445435 | V4: V3PHT202611562425 | W4: 2500000 | X4: CÁT LÁI
A5: 2 | B5: =VLOOKUP(D5,DSKH!$A:$B,2,0) -> A-39 | C5: KHÁCH | D5: TIGER | E5: N | F5: 108201269850 | G5: E31 | H5: 46146 | I5: NL | J5: X | K5: BH | M5: 260401-MFP | N5: HKHCM26045016 | R5: 1 | T5: 3K / 34,9KG | X5: CÁT LÁI
A6: 3 | B6: =VLOOKUP(D6,DSKH!$A:$B,2,0) -> A-39 | C6: KHÁCH | D6: TIGER | E6: N | F6: 108201342650 | G6: E31 | H6: 46146 | I6: NL | J6: X | K6: BH | M6: 0497849 | N6: CMSSH26041680 | R6: 1 | T6: 1K / 378KG | X6: CÁT LÁI
A7: 4 | B7: =VLOOKUP(D7,DSKH!$A:$B,2,0) -> A-39 | C7: KHÁCH | D7: TIGER | E7: N | F7: 108201487700 | G7: E31 | H7: 46146 | I7: NL | J7: X | K7: BH | M7: 60812 | N7: FCO0035227 | R7: 1 | T7: 10K / 110,6KG | X7: SCSC
A8: 5 | B8: =VLOOKUP(D8,DSKH!$A:$B,2,0) -> A-39 | C8: KHÁCH | D8: TIGER | E8: N | F8: 108201888540 | G8: E31 | H8: 46146 | I8: NL | J8: V | K8: BH | M8: 12JE-26-EN99-VG11 | N8: OOLU2323380380 | Q8: 1 | U8: TIIU5180738 | V8: V3PHT202611558851 | W8: 500000 | X8: SP ITC
A9: 6 | B9: =VLOOKUP(D9,DSKH!$A:$B,2,0) -> A-39 | C9: KHÁCH | D9: TIGER | E9: N | F9: 108214433020 | G9: E31 | H9: 46148 | I9: NL | J9: X | K9: BH | M9: STE-VT26006 | N9: TL260426HCM75 | R9: 1 | T9: 1K / 298,45KG | X9: CÁT LÁI
A10: 7 | B10: =VLOOKUP(D10,DSKH!$A:$B,2,0) -> A-27 | C10: KHÁCH | D10: TRUNG ĐÔNG | E10: N | F10: 108201879920 | G10: E31 | H10: 46146 | I10: NL | J10: X | K10: DN3 | M10: IT-SI-12597 | N10: HLCUTA12603FZNZ3 | Q10: 7 | U10: BMOU5622781 FCIU7447520 GCXU5947094 HAMU4070700 HLBU2267900 SEKU6359096 UETU7560694 | X10: CÁT LÁI
A11: 8 | B11: =VLOOKUP(D11,DSKH!$A:$B,2,0) -> A-27 | C11: KHÁCH | D11: TRUNG ĐÔNG | E11: N | F11: 108204380800 | G11: A12 | H11: 46146 | I11: NL | J11: V | K11: DN3 | M11: 40205167 | N11: PCLUINC01545155 | Q11: 8 | U11: DFSU7647477 FSCU8501040 PCLU5112775 PCLU5163026 PCLU5223819 TEMU8886760 TGBU5574096 TIIU6649199 | X11: CÁT LÁI
A12: 9 | B12: =VLOOKUP(D12,DSKH!$A:$B,2,0) -> A-17 | C12: KHÁCH | D12: NHỰA RELIABLE | E12: N | F12: 108216737200 | G12: A12 | H12: 46149 | I12: NL | J12: V | K12: BH | L12: E | M12: INVJYSP260330ZKXS-2587 | N12: YMJAI221205448 | Q12: 10 | U12: BMOU6144917 BMOU6204220 FFAU6998136 TIIU4666900 SEGU6511687 YMMU6623561 YMMU7182389 TGBU5091420 YMLU8668577 YMMU6291981 | V12: V3PHT202611595618 | W12: 5000000 | X12: CÁT LÁI
A13: 10 | B13: =VLOOKUP(D13,DSKH!$A:$B,2,0) -> A-17 | C13: KHÁCH | D13: NHỰA RELIABLE | E13: N | F13: 108216768700 | G13: A12 | H13: 46149 | I13: NL | J13: V | K13: BH | L13: D | M13: INVE-26-00016 | N13: NAY04260484HCM | P13: 1 | U13: SEGU1296658 | V13: V3PHT264078434618 | W13: 250000 | X13: CÁT LÁI
A14: 11 | B14: =VLOOKUP(D14,DSKH!$A:$B,2,0) -> A-213 | C14: THẢO | D14: REGENT | E14: N | F14: 108203315620 | G14: A12 | H14: 46146 | I14: NL | J14: V | K14: NT | L14: E | M14: 20260424001 | N14: LLLHCM26423226 | R14: 1 | T14: 5K/4,792KG | V14: 263572082440 | W14: 71880 | X14: CAT LAI
A15: 12 | B15: =VLOOKUP(D15,DSKH!$A:$B,2,0) -> A-213 | C15: THẢO | D15: REGENT | E15: X | F15: 308492314560 | G15: B11 | H15: 46146 | I15: NL | J15: X | K15: NT | M15: 20 | S15: 1 | T15: 6K/22,15KG
A16: 13 | B16: =VLOOKUP(D16,DSKH!$A:$B,2,0) -> A-213 | C16: THẢO | D16: REGENT | E16: X | F16: 308495483720 | G16: B11 | H16: 46147 | I16: NL | J16: X | K16: NT | M16: 20260504001 | S16: 1 | T16: 154K/5,290,6KG | Y16: TK CHUNG LO
A17: 14 | B17: =VLOOKUP(D17,DSKH!$A:$B,2,0) -> A-213 | C17: THẢO | D17: REGENT | E17: X | F17: 308495505750 | G17: B11 | H17: 46147 | I17: NL | J17: X | K17: NT
A18: 15 | B18: =VLOOKUP(D18,DSKH!$A:$B,2,0) -> A-213 | C18: THẢO | D18: REGENT | E18: X | F18: 308495517100 | G18: B11 | H18: 46147 | I18: NL | J18: X | K18: NT
A19: 16 | B19: =VLOOKUP(D19,DSKH!$A:$B,2,0) -> A-213 | C19: THẢO | D19: REGENT | E19: X | F19: 308495538760 | G19: B11 | H19: 46147 | I19: NL | J19: X | K19: NT
A20: 17 | B20: =VLOOKUP(D20,DSKH!$A:$B,2,0) -> A-224 | C20: THẢO | D20: PU ZHOU | E20: N | F20: 108206082940 | G20: A12 | H20: 46146 | I20: NL | J20: V | K20: NT | L20: E | M20: PZP260402 | N20: LDGHCM2641641SZ | R20: 1 | T20: 4K/3,971KG | V20: 266065321301 | W20: 59565 | X20: CAT LAI
A21: 18 | B21: =VLOOKUP(D21,DSKH!$A:$B,2,0) -> A-556 | C21: THẢO | D21: V.L.I | E21: X | F21: 308493468310 | G21: E52 | H21: 46146 | I21: NL | J21: X | K21: TN | M21: 56-0526-06 VLI-MSY | S21: 1 | T21: 289K/2.257,37KG
A22: 19 | B22: =VLOOKUP(D22,DSKH!$A:$B,2,0) -> A-564 | C22: THẢO | D22: PHOENIX | E22: X | F22: 308492936310 | G22: B11 | H22: 46146 | I22: NL | J22: X | K22: TN | M22: 38 | S22: 1 | T22: 15K/10.283KG
A23: 20 | B23: =VLOOKUP(D23,DSKH!$A:$B,2,0) -> A-502 | C23: THẢO | D23: RYDER | E23: N | F23: 108203697560 | G23: E31 | H23: 46146 | I23: NL | J23: V | K23: DN3 | M23: 2252026 | N23: 4288709165 | R23: 1 | T23: 1K/6,1KG | X23: DHL
A24: 21 | B24: =VLOOKUP(D24,DSKH!$A:$B,2,0) -> A-502 | C24: THẢO | D24: RYDER | E24: N | F24: 108202761660 | G24: A12 | H24: 46146 | I24: MMTB | J24: V | K24: DN3 | M24: VN260428XF-FEDEX-N | N24: 412669261295 | R24: 1 | T24: 2K/3,5KG | X24: FEDEX
A25: 22 | B25: =VLOOKUP(D25,DSKH!$A:$B,2,0) -> A-502 | C25: THẢO | D25: RYDER | E25: N | F25: 108205058840 | G25: E31 | H25: 46146 | I25: NL | J25: X | K25: DN3 | M25: M20260429RIL-FEDEX-HK-B | N25: 412669357398 | R25: 1 | T25: 2K/4,5KG | X25: FEDEX
A26: 23 | B26: =VLOOKUP(D26,DSKH!$A:$B,2,0) -> A-502 | C26: THẢO | D26: RYDER | E26: N | F26: 108205201530 | G26: E31 | H26: 46146 | I26: NL | J26: X | K26: DN3 | M26: M20260429XF-FEDEX-SZ | N26: 412669261332 | R26: 1 | T26: 4K/32,7KG | X26: FEDEX
A27: 24 | B27: =VLOOKUP(D27,DSKH!$A:$B,2,0) -> A-502 | C27: THẢO | D27: RYDER | E27: X | F27: 308491418820 | G27: E62 | H27: 46147 | I27: NL | J27: X | K27: DN3 | M27: RD260506-BOA-VN | R27: 1 | T27: 4K/1.003,1KG | X27: KNQ LF LOGISTICS | Y27: TK CHUNG LO
A28: 25 | B28: =VLOOKUP(D28,DSKH!$A:$B,2,0) -> A-502 | C28: THẢO | D28: RYDER | E28: X | F28: 308491425340 | G28: E62 | H28: 46147 | I28: NL | J28: X | K28: DN3
A29: 26 | B29: =VLOOKUP(D29,DSKH!$A:$B,2,0) -> A-213 | C29: THẢO | D29: REGENT | E29: N | F29: 108210590720 | G29: A12 | H29: 46147 | I29: NL | J29: V | K29: NT | L29: E | M29: 20260418001 | N29: MEDUYO572919 | Q29: 1 | T29: 63K/20.025,1KG | U29: FFAU2975791 | V29: 202611578240 | W29: 500000 | X29: SP-ITC | Y29: TK CHUNG LO 56/SKHCN-TDC
A30: 27 | B30: =VLOOKUP(D30,DSKH!$A:$B,2,0) -> A-213 | C30: THẢO | D30: REGENT | E30: N | F30: 108210609840 | G30: A12 | H30: 46147 | I30: THEP | J30: V | K30: NT | L30: E
A31: 28 | B31: =VLOOKUP(D31,DSKH!$A:$B,2,0) -> A-213 | C31: THẢO | D31: REGENT | E31: X | F31: 308497389450 | G31: B11 | H31: 46147 | I31: NL | J31: X | K31: NT | M31: 20260504002 | S31: 1 | T31: 101K/203,02KG | Y31: TK CHUNG LO
A32: 29 | B32: =VLOOKUP(D32,DSKH!$A:$B,2,0) -> A-213 | C32: THẢO | D32: REGENT | E32: X | F32: 308497401350 | G32: B11 | H32: 46147 | I32: NL | J32: X | K32: NT
A33: 30 | B33: =VLOOKUP(D33,DSKH!$A:$B,2,0) -> A-213 | C33: THẢO | D33: REGENT | E33: X | F33: 308497413360 | G33: B11 | H33: 46147 | I33: NL | J33: X | K33: NT
A34: 31 | B34: =VLOOKUP(D34,DSKH!$A:$B,2,0) -> A-213 | C34: THẢO | D34: REGENT | E34: X | F34: 308498534430 | G34: B11 | H34: 46147 | I34: NL | J34: X | K34: NT | M34: 20260504003 | S34: 1 | T34: 186K/1.425,86KG | Y34: TK CHUNG LO
A35: 32 | B35: =VLOOKUP(D35,DSKH!$A:$B,2,0) -> A-213 | C35: THẢO | D35: REGENT | E35: X | F35: 308498542350 | G35: B11 | H35: 46147 | I35: NL | J35: X | K35: NT
A36: 33 | B36: =VLOOKUP(D36,DSKH!$A:$B,2,0) -> A-213 | C36: THẢO | D36: REGENT | E36: X | F36: 308498548430 | G36: B11 | H36: 46147 | I36: NL | J36: X | K36: NT
A37: 34 | B37: =VLOOKUP(D37,DSKH!$A:$B,2,0) -> A-213 | C37: THẢO | D37: REGENT | E37: X | F37: 308498557420 | G37: B11 | H37: 46147 | I37: NL | J37: X | K37: NT
A38: 35 | B38: =VLOOKUP(D38,DSKH!$A:$B,2,0) -> A-213 | C38: THẢO | D38: REGENT | E38: X | F38: 308498620750 | G38: B11 | H38: 46147 | I38: NL | J38: X | K38: NT | M38: 20260505001 | S38: 1 | T38: 9K/75,51KG
A39: 36 | B39: =VLOOKUP(D39,DSKH!$A:$B,2,0) -> A-323 | C39: THẢO | D39: AICA | E39: N | F39: 108207400710 | G39: A12 | H39: 46147 | I39: NL | J39: V | K39: NT | L39: E | M39: 421/ICA-INV/III/26 | N39: SAA260306602 | P39: 4 | T39: 160K/80.880KG | U39: SKLU1668296 SKLU1922780 SKLU1937570 SKLU2076049 | X39: CAT LAI | Y39: 8MQ-0041777
A40: 37 | B40: =VLOOKUP(D40,DSKH!$A:$B,2,0) -> A-323 | C40: THẢO | D40: AICA | E40: N | F40: 108207767510 | G40: A12 | H40: 46147 | I40: NL | J40: V | K40: NT | L40: RCEP | M40: ALV-26-018 | N40: TYJPVN260846 | Q40: 1 | T40: 48K/5.232KG | U40: TWCU8104180 | X40: CAT LAI
A41: 38 | B41: =VLOOKUP(D41,DSKH!$A:$B,2,0) -> A-213 | C41: THẢO | D41: REGENT | E41: X | F41: 308500491410 | G41: B11 | H41: 46148 | I41: NL | J41: X | K41: NT | M41: 20260505002 | S41: 1 | T41: 195K/14.484,55KG | Y41: TK CHUNG LO
...

Sheet DSKH
A1: DANH SÁCH KHÁCH HÀNG
A2: TÊN | B2: Mã khách hàng | C2: Tên khách hàng | D2: Mã số thuế
A3: AN PHÚ THỊNH | B3: A-01 | C3: CÔNG TY CỔ PHẦN AN PHÚ THỊNH | D3: 3600921992
B4: A-02 | C4: CÔNG TY CỔ PHẦN THIẾT BỊ BÁCH HƯNG | D4: 3603380692
A5: SOVI | B5: A-03 | C5: CÔNG TY CỔ PHẦN BAO BÌ BIÊN HÒA | D5: 3600648493
B6: A-04 | C6: CÔNG TY TNHH BASF VIỆT NAM | D6: 3700238204
A7: CƯỜNG THỊNH | B7: A-05 | C7: CÔNG TY TNHH THƯƠNG MẠI KỸ THUẬT CƯỜNG THỊNH | D7: 3602791481
B8: A-06 | C8: CÔNG TY TNHH ĐẶNG TRUNG QUÂN | D8: 3600953419
A9: HAN BA | B9: A-07 | C9: CÔNG TY TNHH HAN BA | D9: 3600726737
B10: A-08 | C10: CÔNG TY TNHH THƯƠNG MẠI DỊCH VỤ KỸ THUẬT HOẰNG DƯƠNG | D10: 309530820
A11: JAAN-E | B11: A-09 | C11: CÔNG TY TRÁCH NHIỆM HỮU HẠN JAAN-E | D11: 3600813482
A12: KAISER | B12: A-10 | C12: CÔNG TY TNHH KAISER VIỆT NAM | D12: 310176878
B13: A-100 | C13: CÔNG TY TNHH LESCHACO VIỆT NAM | D13: 306573424
B14: A-101 | C14: CÔNG TY TNHH ĐẦU TƯ PHÁT TRIỂN XÂY DỰNG MINH TÂN TIẾN | D14: 3600837797
B15: A-103 | C15: CÔNG TY TNHH CÔNG NGHIỆP PTS | D15: 309999002
B16: A-104 | C16: CÔNG TY TNHH THƯƠNG MẠI THÁI THÀNH | D16: 301379511
B17: A-105 | C17: CÔNG TY TNHH THƯƠNG MẠI NGỌC THIÊM | D17: 3603594158
A18: TRUNG VẠN PHONG | B18: A-689 | C18: CÔNG TY TNHH BÌNH TIÊN ĐỒNG NAI | D18: 3600241531
B19: A-107 | C19: CÔNG TY TNHH RIC CORPORATION LIMITED | D19: 3700886533
B20: A-108 | C20: CÔNG TY TNHH KANGPING TECHNOLOGY (VIỆT NAM) | D20: 3702747084
B21: A-109 | C21: CÔNG TY CỔ PHẦN THAMI SHIPPING & AIRFREIGHT | D21: 303022997
A22: KYC | B22: A-11 | C22: CÔNG TY TNHH MỘT THÀNH VIÊN KYC MACHINE INDUSTRY VIỆT NAM | D22: 3603208839
A23: GĂNG TAY CHU LAI | B23: A-111 | C23: CÔNG TY CỔ PHẦN SẢN XUẤT GĂNG TAY CHU LAI | D23: 4001182818
B24: A-112 | C24: CÔNG TY TNHH SẢN XUẤT THƯƠNG MẠI DỊCH VỤ HUY HOÀNG MINH | D24: 311672678
A25: MATSUYA | B25: A-12 | C25: CÔNG TY TNHH MATSUYA R&D (VIỆT NAM) | D25: 3601000200
B26: A-122 | C26: CÔNG TY CỔ PHẦN THUẬN HIỆP PHÁT | D26: 3602263192
B27: A-123 | C27: CÔNG TY TNHH SẢN XUẤT THƯƠNG MẠI VĨNH PHÁT | D27: 3602313911
B28: A-125 | C28: CÔNG TY TNHH TIN HỌC GIA PHÚC KHANG | D28: 315497191
A29: VÂN LONG CDC | B29: A-128 | C29: CÔNG TY CỔ PHẦN THƯƠNG MẠI ĐẦU TƯ VÂN LONG CDC | D29: 200835768
B30: A-129 | C30: CÔNG TY TNHH SPACE TRADING | D30: 315665872
A31: MẬU DƯƠNG | B31: A-13 | C31: CÔNG TY TNHH MẬU DƯƠNG | D31: 3701671604
B32: A-130 | C32: CÔNG TY TNHH SẢN XUẤT - THƯƠNG MẠI - DỊCH VỤ HOÀNG ĐÔNG | D32: 3600974578
A33: OPTIMA/LYNN | B33: A-131 | C33: CÔNG TY TNHH OPTIMA POWER TOOLS VIỆT NAM | D33: 3603652025
A34: RONGBAOYU | B34: A-132 | C34: CÔNG TY TNHH RONGBAOYU (VIỆT NAM) | D34: 3603680801
B35: A-135 | C35: CÔNG TY TNHH TIẾP VẬN THỰC | D35: 309561064
B36: A-137 | C36: CÔNG TY TNHH HOYER TRANSPORT VIỆT NAM | D36: 310241781
B37: A-138 | C37: CÔNG TY TNHH K&H WALKER SHOES | D37: 3702805836
B38: A-139 | C38: CÔNG TY TNHH LYNN SUPPLY CHAIN (VIETNAM) | D38: 316039860
A39: NEW-TQQT | B39: B-57 | C39: CÔNG TY TNHH NEW VIỆT NAM | D39: 3600545709
B40: A-140 | C40: CÔNG TY TNHH TM - DV P.T & F | D40: 3602580441
...
